Workbook

Sheet Janeiro2023
A2: EXTRATO DE MOVIMENTAÇÃO
A4: Banco | B4: LEPTA BANK (274) | C4: Agência | D4: 1 | E4: Conta | F4: 08198095-5
A5: Empresa | B5: TRANSP. TURISTICA BENFICA S.A | C5: Saldo Anterior | D5: 0 | F5: Saldo Disponível
A6: CNPJ | B6: 59.275.289/0001-02 | C6: Totais (Entradas/Saídas) | D6: =SUM(D9:D609) -> 3471533.7 | E6: =SUM(E9:E609) -> 248957.67 | F6: =F609 -> 3222576
A8: Data | B8: Histórico | C8: Complemento | D8: Créditos | E8: Débitos | F8: Saldo
A9: 44938 | B9: Crédito em conta | C9: TRANSPORTADORA TURISTICA BENFICA S.A | D9: 1000 | F9: =D9-E9+D5 -> 1000
A10: 44938 | B10: Gestão de caixa | E10: =(D9*0.005)+10 -> 15 | F10: =D10-E10+F9 -> 985
A11: 44939 | B11: Transferência entre contas | C11: TRANSPORTADORA TURISTICA BENFICA S.A | E11: 450 | F11: =D11-E11+F10 -> 535
A12: 44944 | B12: Crédito em conta | C12: TRANSPORTADORA TURISTICA BENFICA S.A | D12: 3445000 | F12: =D12-E12+F11 -> 3445535
A13: 44944 | B13: Gestão de caixa | E13: =(D12*0.005)+10 -> 17235 | F13: =D13-E13+F12 -> 3428300
A14: 44946 | B14: Transferência entre contas | C14: TRANSPORTADORA TURISTICA BENFICA S.A | E14: 111500 | F14: =D14-E14+F13 -> 3316800
A15: 44946 | B15: Transferência entre contas | C15: TRANSPORTADORA TURISTICA BENFICA S.A | E15: 35000 | F15: =D15-E15+F14 -> 3281800
A16: 44950 | B16: Transferência entre contas | C16: TRANSPORTADORA TURISTICA BENFICA S.A | E16: 75600 | F16: =D16-E16+F15 -> 3206200
A17: 44953 | B17: Transferência entre contas | C17: TRANSPORTADORA TURISTICA BENFICA S.A | E17: 9000 | F17: =D17-E17+F16 -> 3197200
A18: 44953 | B18: Crédito em conta | C18: TRANSPORTADORA TURISTICA BENFICA S.A | D18: 6556.11 | F18: =D18-E18+F17 -> 3203756.1
A19: 44953 | B19: Gestão de caixa | E19: =(D18*0.005)+10 -> 42.78055 | F19: =D19-E19+F18 -> 3203713.3
A20: 44956 | B20: Crédito em conta | C20: TRANSPORTADORA TURISTICA BENFICA S.A | D20: 14727.55 | F20: =D20-E20+F19 -> 3218440.9
A21: 44956 | B21: Gestão de caixa | E21: =(D20*0.005)+10 -> 83.63775 | F21: =D21-E21+F20 -> 3218357.2
A22: 44957 | B22: Crédito em conta | C22: TRANSPORTADORA TURISTICA BENFICA S.A | D22: 4250 | F22: =D22-E22+F21 -> 3222607.2
A23: 44957 | B23: Gestão de caixa | E23: =(D22*0.005)+10 -> 31.25 | F23: =D23-E23+F22 -> 3222576
F24: =D24-E24+F23 -> 3222576
F25: =D25-E25+F24 -> 3222576
F26: =D26-E26+F25 -> 3222576
F27: =D27-E27+F26 -> 3222576
F28: =D28-E28+F27 -> 3222576
F29: =D29-E29+F28 -> 3222576
F30: =D30-E30+F29 -> 3222576
F31: =D31-E31+F30 -> 3222576
F32: =D32-E32+F31 -> 3222576
F33: =D33-E33+F32 -> 3222576
F34: =D34-E34+F33 -> 3222576
F35: =D35-E35+F34 -> 3222576
... F609: =D609-E609+F608 -> 3222576

Sheet Fevereiro2023
A2: EXTRATO DE MOVIMENTAÇÃO
A4: Banco | B4: LEPTA BANK (274) | C4: Agência | D4: 1 | E4: Conta | F4: 08198095-5
A5: Empresa | B5: TRANSP. TURISTICA BENFICA S.A | C5: Saldo Anterior | D5: =Janeiro2023!F6 -> 3222576 | F5: Saldo Disponível
A6: CNPJ | B6: 59.275.289/0001-02 | C6: Totais (Entradas/Saídas) | D6: =SUM(D9:D609) -> 655663.83 | E6: =SUM(E9:E609) -> 897524.44 | F6: =F609 -> 2980715.4
A8: Data | B8: Histórico | C8: Complemento | D8: Créditos | E8: Débitos | F8: Saldo
A9: 44958 | B9: Crédito em conta | C9: BENFICA CARGAS E LOGISTICA S.A | D9: 12000 | F9: =D9-E9+D5 -> 3234576
A10: 44958 | B10: Gestão de caixa | E10: =(D9*0.005)+10 -> 70 | F10: =D10-E10+F9 -> 3234506
A11: 44958 | B11: Transferência entre contas | C11: TRANSPORTADORA TURISTICA BENFICA S.A | E11: 112000 | F11: =D11-E11+F10 -> 3122506
A12: 44958 | B12: Crédito em conta | C12: TRANSPORTADORA TURISTICA BENFICA AS | D12: 20000 | F12: =D12-E12+F11 -> 3142506
A13: 44958 | B13: Gestão de caixa | E13: =(D12*0.005)+10 -> 110 | F13: =D13-E13+F12 -> 3142396
A14: 44959 | B14: Transferência entre contas | C14: TRANSPORTADORA TURISTICA BENFICA S.A | E14: 12000 | F14: =D14-E14+F13 -> 3130396
A15: 44960 | B15: Tarifa de manutenção de conta | C15: TRANSPORTADORA TURISTICA BENFICA S.A | E15: 1358.06 | F15: =D15-E15+F14 -> 3129037.9
A16: 44960 | B16: Transferência entre contas | C16: TRANSPORTADORA TURISTICA BENFICA S.A | E16: 14000 | F16: =D16-E16+F15 -> 3115037.9
A17: 44963 | B17: Crédito em conta | C17: UNIVERSAL TURISMO LTDA-EPP | D17: 18000 | F17: =D17-E17+F16 -> 3133037.9
A18: 44963 | B18: Gestão de caixa | E18: =(D17*0.005)+10 -> 100 | F18: =D18-E18+F17 -> 3132937.9
A19: 44963 | B19: Transferência entre contas | C19: TRANSPORTADORA TURISTICA BENFICA S.A | E19: 261000 | F19: =D19-E19+F18 -> 2871937.9
A20: 44963 | B20: Transferência entre contas | C20: TRANSPORTADORA TURISTICA BENFICA S.A | E20: 16000 | F20: =D20-E20+F19 -> 2855937.9
A21: 44964 | B21: Transferência entre contas | C21: TRANSPORTADORA TURISTICA BENFICA S.A | E21: 50000 | F21: =D21-E21+F20 -> 2805937.9
A22: 44965 | B22: Crédito em conta | C22: PATRIMONY ADMINISTRADORA DE BENS AS | D22: 180030.83 | F22: =D22-E22+F21 -> 2985968.8
A23: 44965 | B23: Gestão de caixa | E23: =(D22*0.005)+10 -> 910.15415 | F23: =D23-E23+F22 -> 2985058.6
A24: 44965 | B24: Crédito em conta | C24: TRANSPORTADORA TURISTICA BENFICA AS | D24: 90000 | F24: =D24-E24+F23 -> 3075058.6
A25: 44965 | B25: Gestão de caixa | E25: =(D24*0.005)+10 -> 460 | F25: =D25-E25+F24 -> 3074598.6
A26: 44965 | B26: Transferência entre contas | C26: TRANSPORTADORA TURISTICA BENFICA S.A | E26: 3000 | F26: =D26-E26+F25 -> 3071598.6
A27: 44965 | B27: Tarifa de manutenção de conta | C27: TRANSPORTADORA TURISTICA BENFICA S.A - (Empresa) | E27: 1258.06 | F27: =D27-E27+F26 -> 3070340.5
A28: 44965 | B28: Crédito em conta | C28: MENDES FERREIRA AGRICOLA LTDA | D28: 4050 | F28: =D28-E28+F27 -> 3074390.5
A29: 44965 | B29: Gestão de caixa | E29: =(D28*0.005)+10 -> 30.25 | F29: =D29-E29+F28 -> 3074360.3
A30: 44966 | B30: Crédito em conta | C30: TRANSPORTADORA TURISTICA BENFICA AS | D30: 255000 | F30: =D30-E30+F29 -> 3329360.3
A31: 44966 | B31: Gestão de caixa | E31: =(D30*0.005)+10 -> 1285 | F31: =D31-E31+F30 -> 3328075.3
A32: 44967 | B32: Transferência entre contas | C32: TRANSPORTADORA TURISTICA BENFICA S.A | E32: 14000 | F32: =D32-E32+F31 -> 3314075.3
A33: 44967 | B33: Crédito em conta | C33: AGROCANA A N H LTDA. | D33: 8000 | F33: =D33-E33+F32 -> 3322075.3
A34: 44967 | B34: Gestão de caixa | E34: =(D33*0.005)+10 -> 50 | F34: =D34-E34+F33 -> 3322025.3
A35: 44967 | B35: Crédito em conta | C35: AGROCANA A N H LTDA. | D35: 1333 | F35: =D35-E35+F34 -> 3323358.3
A36: 44967 | B36: Gestão de caixa | E36: =(D35*0.005)+10 -> 16.665 | F36: =D36-E36+F35 -> 3323341.6
A37: 44967 | B37: Crédito em conta | C37: AGROCANA A N H LTDA. | D37: 8000 | F37: =D37-E37+F36 -> 3331341.6
A38: 44967 | B38: Gestão de caixa | E38: =(D37*0.005)+10 -> 50 | F38: =D38-E38+F37 -> 3331291.6
A39: 44972 | B39: Transferência entre contas | C39: TRANSPORTADORA TURISTICA BENFICA S.A | E39: 58000 | F39: =D39-E39+F38 -> 3273291.6
A40: 44973 | B40: Transferência entre contas | C40: TRANSPORTADORA TURISTICA BENFICA S.A | E40: 35500 | F40: =D40-E40+F39 -> 3237791.6
A41: 44974 | B41: Transferência entre contas | C41: TRANSPORTADORA TURISTICA BENFICA S.A | E41: 182000 | F41: =D41-E41+F40 -> 3055791.6
A42: 44980 | B42: Crédito em conta | C42: JOSE AILTON F CONCEICAO | D42: 1250 | F42: =D42-E42+F41 -> 3057041.6
A43: 44980 | B43: Gestão de caixa | E43: =(D42*0.005)+10 -> 16.25 | F43: =D43-E43+F42 -> 3057025.4
...

Sheet Março2023
A2: EXTRATO DE MOVIMENTAÇÃO
A4: Banco | B4: LEPTA BANK (274) | C4: Agência | D4: 1 | E4: Conta | F4: 08198095-5
A5: Empresa | B5: TRANSP. TURISTICA BENFICA S.A | C5: Saldo Anterior | D5: =Fevereiro2023!F6 -> 2980715.4 | F5: Saldo Disponível
A6: CNPJ | B6: 59.275.289/0001-02 | C6: Totais (Entradas/Saídas) | D6: =SUM(D9:D609) -> 854448.93 | E6: =SUM(E9:E609) -> 1094712.3 | F6: =F609 -> 2740452.1
A8: Data | B8: Histórico | C8: Complemento | D8: Créditos | E8: Débitos | F8: Saldo
A9: 44986 | B9: Transferência entre contas | C9: TRANSPORTADORA TURISTICA BENFICA S.A | E9: 45000 | F9: =D9-E9+D5 -> 2935715.4
A10: 44986 | B10: Crédito em conta | C10: PERFFICE DO BRASIL SERVICOS DE TRANSPORTE E LOGISTICA | D10: 20430 | F10: =D10-E10+F9 -> 2956145.4
A11: 44986 | B11: Gestão de caixa | E11: =(D10*0.005)+10 -> 112.15 | F11: =D11-E11+F10 -> 2956033.2
A12: 44987 | B12: Crédito em conta | C12: BENFICA CARGAS E LOGISTICA S.A | D12: 13000 | F12: =D12-E12+F11 -> 2969033.2
A13: 44987 | B13: Gestão de caixa | E13: =(D12*0.005)+10 -> 75 | F13: =D13-E13+F12 -> 2968958.2
A14: 44988 | B14: Tarifa de manutenção de conta | C14: TRANSPORTADORA TURISTICA BENFICA S.A - (Vinculada) | E14: 1500 | F14: =D14-E14+F13 -> 2967458.2
A15: 44988 | B15: Tarifa de manutenção da conta | C15: TED's, PIX e demais | E15: 280 | F15: =D15-E15+F14 -> 2967178.2
A16: 44988 | B16: Transferência entre contas | C16: TRANSPORTADORA TURISTICA BENFICA S.A | E16: 193000 | F16: =D16-E16+F15 -> 2774178.2
A17: 44991 | B17: Transferência entre contas | C17: TRANSPORTADORA TURISTICA BENFICA S.A | E17: 122000 | F17: =D17-E17+F16 -> 2652178.2
A18: 44992 | B18: Crédito em conta | C18: BY BUS TRANSPORTES LTDA | D18: 22483.31 | F18: =D18-E18+F17 -> 2674661.5
A19: 44992 | B19: Gestão de caixa | E19: =(D18*0.005)+10 -> 122.41655 | F19: =D19-E19+F18 -> 2674539.1
A20: 44992 | B20: Crédito em conta | C20: TRANSPORTADORA TURISTICA BENFICA AS | D20: 51000 | F20: =D20-E20+F19 -> 2725539.1
A21: 44992 | B21: Gestão de caixa | E21: =(D20*0.005)+10 -> 265 | F21: =D21-E21+F20 -> 2725274.1
A22: 44992 | B22: Tarifa de manutenção de conta | C22: TRANSPORTADORA TURISTICA BENFICA S.A - (Empresa) | E22: 1500 | F22: =D22-E22+F21 -> 2723774.1
A23: 44993 | B23: Transferência entre contas | C23: TRANSPORTADORA TURISTICA BENFICA S.A | E23: 8000 | F23: =D23-E23+F22 -> 2715774.1
A24: 44993 | B24: Crédito em conta | C24: PATRIMONY ADMINISTRADORA DE BENS AS | D24: 180030.83 | F24: =D24-E24+F23 -> 2895805
A25: 44993 | B25: Gestão de caixa | E25: =(D24*0.005)+10 -> 910.15415 | F25: =D25-E25+F24 -> 2894894.8
A26: 44994 | B26: Transferência entre contas | C26: TRANSPORTADORA TURISTICA BENFICA S.A | E26: 3000 | F26: =D26-E26+F25 -> 2891894.8
A27: 44994 | B27: Crédito em conta | C27: OUROESTE BIOENERGIA LTDA | D27: 19958.92 | F27: =D27-E27+F26 -> 2911853.7
A28: 44994 | B28: Gestão de caixa | E28: =(D27*0.005)+10 -> 109.7946 | F28: =D28-E28+F27 -> 2911743.9
A29: 44995 | B29: Transferência entre contas | C29: TRANSPORTADORA TURISTICA BENFICA S.A | E29: 97000 | F29: =D29-E29+F28 -> 2814743.9
A30: 44995 | B30: Crédito em conta | C30: TRANSPORTADORA TURISTICA BENFICA S.A | D30: 18330 | F30: =D30-E30+F29 -> 2833073.9
A31: 44995 | B31: Gestão de caixa | E31: =(D30*0.005)+10 -> 101.65 | F31: =D31-E31+F30 -> 2832972.3
A32: 44995 | B32: Crédito em conta | C32: GUARIROBA BIOENERGIA LTDA | D32: 124486.37 | F32: =D32-E32+F31 -> 2957458.6
A33: 44995 | B33: Gestão de caixa | E33: =(D32*0.005)+10 -> 632.43185 | F33: =D33-E33+F32 -> 2956826.2
A34: 44995 | B34: Crédito em conta | C34: MOEMA BIOENERGIA S A | D34: 260234.27 | F34: =D34-E34+F33 -> 3217060.5
A35: 44995 | B35: Gestão de caixa | E35: =(D34*0.005)+10 -> 1311.1714 | F35: =D35-E35+F34 -> 3215749.3
A36: 44995 | B36: Transferência entre contas | C36: TRANSPORTADORA TURISTICA BENFICA S.A | E36: 14000 | F36: =D36-E36+F35 -> 3201749.3
A37: 44995 | B37: Ajuste de Saldo | D37: 0.01 | F37: =D37-E37+F36 -> 3201749.3
A38: 44999 | B38: Transferência entre contas | C38: TRANSPORTADORA TURISTICA BENFICA S.A | E38: 48000 | F38: =D38-E38+F37 -> 3153749.3
A39: 45000 | B39: Transferência entre contas | C39: TRANSPORTADORA TURISTICA BENFICA S.A | E39: 53000 | F39: =D39-E39+F38 -> 3100749.3
A40: 45000 | B40: Crédito em conta | C40: BY BUS TRANSPORTES LTDA | D40: 18000 | F40: =D40-E40+F39 -> 3118749.3
A41: 45000 | B41: Gestão de caixa | E41: =(D40*0.005)+10 -> 100 | F41: =D41-E41+F40 -> 3118649.3
A42: 45001 | B42: Crédito em conta | C42: TRANSPORTADORA TURISTICA BENFICA AS | D42: 26000 | F42: =D42-E42+F41 -> 3144649.3
A43: 45001 | B43: Gestão de caixa | E43: =(D42*0.005)+10 -> 140 | F43: =D43-E43+F42 -> 3144509.3
...

Sheet Abril2023
A2: EXTRATO DE MOVIMENTAÇÃO
A4: Banco | B4: LEPTA BANK (274) | C4: Agência | D4: 1 | E4: Conta | F4: 08198095-5
A5: Empresa | B5: TRANSP. TURISTICA BENFICA S.A | C5: Saldo Anterior | D5: =Março2023!F6 -> 2740452.1 | F5: Saldo Disponível
A6: CNPJ | B6: 59.275.289/0001-02 | C6: Totais (Entradas/Saídas) | D6: =SUM(D9:D609) -> 1005404.5 | E6: =SUM(E9:E609) -> 968667.03 | F6: =F609 -> 2777189.5
A8: Data | B8: Histórico | C8: Complemento | D8: Créditos | E8: Débitos | F8: Saldo
A9: 45019 | B9: Tarifa de manutenção de conta | C9: TRANSPORTADORA TURISTICA BENFICA S.A - (Vinculada) | E9: 1500 | F9: =D9-E9+D5 -> 2738952.1
A10: 45019 | B10: Tarifa de manutenção da conta | C10: TED's, PIX e demais | E10: 460 | F10: =D10-E10+F9 -> 2738492.1
A11: 45021 | B11: Crédito em conta | C11: BB TRANSPORTE E TURISMO LTDA | D11: 90000 | F11: =D11-E11+F10 -> 2828492.1
A12: 45021 | B12: Gestão de caixa | E12: =(D11*0.005)+10 -> 460 | F12: =D12-E12+F11 -> 2828032.1
A13: 45021 | B13: Transferência entre contas | C13: TRANSPORTADORA TURISTICA BENFICA S.A | E13: 188000 | F13: =D13-E13+F12 -> 2640032.1
A14: 45021 | B14: Tarifa de manutenção de conta | C14: TRANSPORTADORA TURISTICA BENFICA S.A - (Empresa) | E14: 1500 | F14: =D14-E14+F13 -> 2638532.1
A15: 45022 | B15: Transferência entre contas | C15: TRANSPORTADORA TURISTICA BENFICA S.A | E15: 163500 | F15: =D15-E15+F14 -> 2475032.1
A16: 45022 | B16: Crédito em conta | C16: TRANSPORTADORA TURISTICA BENFICA S.A | D16: 18000 | F16: =D16-E16+F15 -> 2493032.1
A17: 45022 | B17: Gestão de caixa | E17: =(D16*0.005)+10 -> 100 | F17: =D17-E17+F16 -> 2492932.1
A18: 45022 | B18: Crédito em conta | C18: BY BUS TRANSPORTES LTDA | D18: 22483.31 | F18: =D18-E18+F17 -> 2515415.4
A19: 45022 | B19: Gestão de caixa | E19: =(D18*0.005)+10 -> 122.41655 | F19: =D19-E19+F18 -> 2515293
A20: 45026 | B20: Crédito em conta | C20: PATRIMONY ADMINISTRADORA DE BENS AS | D20: 180030.83 | F20: =D20-E20+F19 -> 2695323.8
A21: 45026 | B21: Gestão de caixa | E21: =(D20*0.005)+10 -> 910.15415 | F21: =D21-E21+F20 -> 2694413.6
A22: 45026 | B22: Crédito em conta | C22: AGROCANA A N H LTDA. | D22: 26000 | F22: =D22-E22+F21 -> 2720413.6
A23: 45026 | B23: Gestão de caixa | E23: =(D22*0.005)+10 -> 140 | F23: =D23-E23+F22 -> 2720273.6
A24: 45026 | B24: Crédito em conta | C24: GUARIROBA BIOENERGIA LTDA | D24: 133564.29 | F24: =D24-E24+F23 -> 2853837.9
A25: 45026 | B25: Gestão de caixa | E25: =(D24*0.005)+10 -> 677.82145 | F25: =D25-E25+F24 -> 2853160.1
A26: 45026 | B26: Crédito em conta | C26: OUROESTE BIOENERGIA LTDA | D26: 20411.96 | F26: =D26-E26+F25 -> 2873572.1
A27: 45026 | B27: Gestão de caixa | E27: =(D26*0.005)+10 -> 112.0598 | F27: =D27-E27+F26 -> 2873460
A28: 45026 | B28: Transferência entre contas | C28: TRANSPORTADORA TURISTICA BENFICA S.A | E28: 123500 | F28: =D28-E28+F27 -> 2749960
A29: 45026 | B29: Crédito em conta | C29: MOEMA BIOENERGIA S A | D29: 262470.43 | F29: =D29-E29+F28 -> 3012430.4
A30: 45026 | B30: Gestão de caixa | E30: =(D29*0.005)+10 -> 1322.3521 | F30: =D30-E30+F29 -> 3011108.1
A31: 45026 | B31: Crédito em conta | C31: RENATO HAAG DA SILVA | D31: 85357.03 | F31: =D31-E31+F30 -> 3096465.1
A32: 45026 | B32: Gestão de caixa | E32: =(D31*0.005)+10 -> 436.78515 | F32: =D32-E32+F31 -> 3096028.3
A33: 45028 | B33: Crédito em conta | C33: TRANSPORTADORA TURISTICA BENFICA AS | D33: 18000 | F33: =D33-E33+F32 -> 3114028.3
A34: 45028 | B34: Gestão de caixa | E34: =(D33*0.005)+10 -> 100 | F34: =D34-E34+F33 -> 3113928.3
A35: 45028 | B35: Crédito em conta | C35: SANCETUR - SANTA CECILIA TURISMO LTDA | D35: 18000 | F35: =D35-E35+F34 -> 3131928.3
A36: 45028 | B36: Gestão de caixa | E36: =(D35*0.005)+10 -> 100 | F36: =D36-E36+F35 -> 3131828.3
A37: 45028 | B37: Crédito em conta | C37: ARENA FUTIBA LTDA | D37: 27000 | F37: =D37-E37+F36 -> 3158828.3
A38: 45028 | B38: Gestão de caixa | E38: =(D37*0.005)+10 -> 145 | F38: =D38-E38+F37 -> 3158683.3
A39: 45033 | B39: Transferência entre contas | C39: TRANSPORTADORA TURISTICA BENFICA S.A | E39: 67000 | F39: =D39-E39+F38 -> 3091683.3
A40: 45033 | B40: Transferência entre contas | C40: TRANSPORTADORA TURISTICA BENFICA S.A | E40: 12000 | F40: =D40-E40+F39 -> 3079683.3
A41: 45033 | B41: Crédito em conta | C41: BY BUS TRANSPORTES LTDA | D41: 17100 | F41: =D41-E41+F40 -> 3096783.3
A42: 45033 | B42: Gestão de caixa | E42: =(D41*0.005)+10 -> 95.5 | F42: =D42-E42+F41 -> 3096687.8
A43: 45034 | B43: Transferência entre contas | C43: TRANSPORTADORA TURISTICA BENFICA S.A | E43: 9000 | F43: =D43-E43+F42 -> 3087687.8
...

Sheet Maio2023
A2: EXTRATO DE MOVIMENTAÇÃO
A4: Banco | B4: LEPTA BANK (274) | C4: Agência | D4: 1 | E4: Conta | F4: 08198095-5
A5: Empresa | B5: TRANSP. TURISTICA BENFICA S.A | C5: Saldo Anterior | D5: =Abril2023!F6 -> 2777189.5 | F5: Saldo Disponível
A6: CNPJ | B6: 59.275.289/0001-02 | C6: Totais (Entradas/Saídas) | D6: =SUM(D9:D609) -> 2312808.2 | E6: =SUM(E9:E609) -> 1154434 | F6: =F609 -> 3935563.7
A8: Data | B8: Histórico | C8: Complemento | D8: Créditos | E8: Débitos | F8: Saldo
A9: 45048 | B9: Transferência entre contas | C9: TRANSPORTADORA TURISTICA BENFICA S.A | E9: 35000 | F9: =D9-E9+D5 -> 2742189.5
A10: 45048 | B10: Crédito em conta | C10: TRANSPORTADORA TUR BENFICA S A | D10: 20947.55 | F10: =D10-E10+F9 -> 2763137
A11: 45048 | B11: Gestão de caixa | E11: =(D10*0.005)+10 -> 114.73775 | F11: =D11-E11+F10 -> 2763022.3
A12: 45048 | B12: Crédito em conta | C12: PERFICE DO BRASIL SERVICOS DE | D12: 20430 | F12: =D12-E12+F11 -> 2783452.3
A13: 45048 | B13: Gestão de caixa | E13: =(D12*0.005)+10 -> 112.15 | F13: =D13-E13+F12 -> 2783340.2
A14: 45049 | B14: Tarifa de manutenção de conta | C14: TRANSPORTADORA TURISTICA BENFICA S.A - (Vinculada) | E14: 1500 | F14: =D14-E14+F13 -> 2781840.2
A15: 45049 | B15: Tarifa de manutenção de conta | C15: TED's, PIX e demais | E15: 300 | F15: =D15-E15+F14 -> 2781540.2
A16: 45049 | B16: Transferência entre contas | C16: TRANSPORTADORA TURISTICA BENFICA S.A | E16: 10500 | F16: =D16-E16+F15 -> 2771040.2
A17: 45050 | B17: Crédito em conta | C17: BENFICA CARGAS E LOGISTICA S.A | D17: 32000 | F17: =D17-E17+F16 -> 2803040.2
A18: 45050 | B18: Gestão de caixa | E18: =(D17*0.005)+10 -> 170 | F18: =D18-E18+F17 -> 2802870.2
A19: 45050 | B19: Crédito em conta | C19: TRANSPORTADORA TURISTICA BENFICA S.A | D19: 59000 | F19: =D19-E19+F18 -> 2861870.2
A20: 45050 | B20: Gestão de caixa | E20: =(D19*0.005)+10 -> 305 | F20: =D20-E20+F19 -> 2861565.2
A21: 45050 | B21: Crédito em conta | C21: MIGUEL ARAUJO GIMENEZ | D21: 30000 | F21: =D21-E21+F20 -> 2891565.2
A22: 45050 | B22: Gestão de caixa | E22: =(D21*0.005)+10 -> 160 | F22: =D22-E22+F21 -> 2891405.2
A23: 45051 | B23: Crédito em conta | C23: BB TRANSPORTE E TURISMO LTDA | D23: 90000 | F23: =D23-E23+F22 -> 2981405.2
A24: 45051 | B24: Gestão de caixa | E24: =(D23*0.005)+10 -> 460 | F24: =D24-E24+F23 -> 2980945.2
A25: 45051 | B25: Transferência entre contas | C25: TRANSPORTADORA TURISTICA BENFICA S.A | E25: 228500 | F25: =D25-E25+F24 -> 2752445.2
A26: 45051 | B26: Transferência entre contas | C26: TRANSPORTADORA TURISTICA BENFICA S.A | E26: 82000 | F26: =D26-E26+F25 -> 2670445.2
A27: 45051 | B27: Crédito em conta | C27: MIGUEL ARAUJO GIMENEZ | D27: 6000 | F27: =D27-E27+F26 -> 2676445.2
A28: 45051 | B28: Gestão de caixa | E28: =(D27*0.005)+10 -> 40 | F28: =D28-E28+F27 -> 2676405.2
A29: 45054 | B29: Transferência entre contas | C29: TRANSPORTADORA TURISTICA BENFICA S.A | E29: 65000 | F29: =D29-E29+F28 -> 2611405.2
A30: 45054 | B30: Tarifa de manutenção de conta | C30: TRANSPORTADORA TURISTICA BENFICA S.A - (Empresa) | E30: 1500 | F30: =D30-E30+F29 -> 2609905.2
A31: 45054 | B31: Crédito em conta | C31: PATRIMONY ADMINISTRADORA DE BENS AS | D31: 1180030.8 | F31: =D31-E31+F30 -> 3789936
A32: 45054 | B32: Gestão de caixa | E32: =(D31*0.005)+10 -> 5910.1542 | F32: =D32-E32+F31 -> 3784025.8
A33: 45055 | B33: Crédito em conta | C33: BY BUS TRANSPORTES LTDA | D33: 22483.31 | F33: =D33-E33+F32 -> 3806509.1
A34: 45055 | B34: Gestão de caixa | E34: =(D33*0.005)+10 -> 122.41655 | F34: =D34-E34+F33 -> 3806386.7
A35: 45055 | B35: Ajuste de Saldo | D35: 0.01 | F35: =D35-E35+F34 -> 3806386.7
A36: 45055 | B36: Transferência entre contas | C36: TRANSPORTADORA TURISTICA BENFICA S.A | E36: 39000 | F36: =D36-E36+F35 -> 3767386.7
A37: 45055 | B37: Crédito em conta | C37: OUROESTE BIOENERGIA LTDA | D37: 19946.43 | F37: =D37-E37+F36 -> 3787333.2
A38: 45055 | B38: Gestão de caixa | E38: =(D37*0.005)+10 -> 109.73215 | F38: =D38-E38+F37 -> 3787223.4
A39: 45055 | B39: Crédito em conta | C39: GUARIROBA BIOENERGIA LTDA | D39: 161546.23 | F39: =D39-E39+F38 -> 3948769.7
A40: 45055 | B40: Gestão de caixa | E40: =(D39*0.005)+10 -> 817.73115 | F40: =D40-E40+F39 -> 3947951.9
A41: 45055 | B41: Crédito em conta | C41: MOEMA BIOENERGIA S A | D41: 317084.51 | F41: =D41-E41+F40 -> 4265036.4
A42: 45055 | B42: Gestão de caixa | E42: =(D41*0.005)+10 -> 1595.4226 | F42: =D42-E42+F41 -> 4263441
A43: 45055 | B43: Crédito em conta | C43: AGROCANA A N H LTDA | D43: 26000 | F43: =D43-E43+F42 -> 4289441
...

Sheet Junho2023
A2: EXTRATO DE MOVIMENTAÇÃO
A4: Banco | B4: LEPTA BANK (274) | C4: Agência | D4: 1 | E4: Conta | F4: 08198095-5
A5: Empresa | B5: TRANSP. TURISTICA BENFICA S.A | C5: Saldo Anterior | D5: =Maio2023!F6 -> 3935563.7 | F5: Saldo Disponível
A6: CNPJ | B6: 59.275.289/0001-02 | C6: Totais (Entradas/Saídas) | D6: =SUM(D9:D609) -> 1473498 | E6: =SUM(E9:E609) -> 1097197.5 | F6: =F609 -> 4311864.2
A8: Data | B8: Histórico | C8: Complemento | D8: Créditos | E8: Débitos | F8: Saldo
A9: 45078 | B9: Transferência entre contas | C9: TRANSPORTADORA TURISTICA BENFICA S.A | E9: 37000 | F9: =D9-E9+D5 -> 3898563.7
A10: 45078 | B10: Transferência entre contas | C10: TRANSPORTADORA TURISTICA BENFICA S.A | E10: 8000 | F10: =D10-E10+F9 -> 3890563.7
A11: 45080 | B11: Tarifa de manutenção de conta | C11: TRANSPORTADORA TURISTICA BENFICA S.A - (Vinculada) | E11: 1500 | F11: =D11-E11+F10 -> 3889063.7
A12: 45080 | B12: Tarifa de manutenção da conta | C12: TED's, PIX e demais | E12: 440 | F12: =D12-E12+F11 -> 3888623.7
A13: 45082 | B13: Crédito em conta | C13: BB TRANSPORTE E TURISMO LTDA | D13: 90000 | F13: =D13-E13+F12 -> 3978623.7
A14: 45082 | B14: Gestão de caixa | E14: =(D13*0.005)+10 -> 460 | F14: =D14-E14+F13 -> 3978163.7
A15: 45082 | B15: Transferência entre contas | C15: TRANSPORTADORA TURISTICA BENFICA S.A | E15: 132000 | F15: =D15-E15+F14 -> 3846163.7
A16: 45083 | B16: Transferência entre contas | C16: TRANSPORTADORA TURISTICA BENFICA S.A | E16: 37000 | F16: =D16-E16+F15 -> 3809163.7
A17: 45083 | B17: Transferência entre contas | C17: TRANSPORTADORA TURISTICA BENFICA S.A | E17: 87000 | F17: =D17-E17+F16 -> 3722163.7
A18: 45083 | B18: Crédito em conta | C18: ROGERIO SOARES MARQUES | D18: 4000 | F18: =D18-E18+F17 -> 3726163.7
A19: 45083 | B19: Gestão de caixa | E19: =(D18*0.005)+10 -> 30 | F19: =D19-E19+F18 -> 3726133.7
A20: 45084 | B20: Transferência entre contas | C20: TRANSPORTADORA TURISTICA BENFICA S.A | E20: 64000 | F20: =D20-E20+F19 -> 3662133.7
A21: 45084 | B21: Tarifa de manutenção de conta | C21: TRANSPORTADORA TURISTICA BENFICA S.A - (Empresa) | E21: 1500 | F21: =D21-E21+F20 -> 3660633.7
A22: 45086 | B22: Crédito em conta | C22: PATRIMONY ADMINISTRADORA DE BENS AS | D22: 152544 | F22: =D22-E22+F21 -> 3813177.7
A23: 45086 | B23: Gestão de caixa | E23: =(D22*0.005)+10 -> 772.72 | F23: =D23-E23+F22 -> 3812405
A24: 45086 | B24: Crédito em conta | C24: OUROESTE BIOENERGIA LTDA | D24: 21478.61 | F24: =D24-E24+F23 -> 3833883.6
A25: 45086 | B25: Gestão de caixa | E25: =(D24*0.005)+10 -> 117.39305 | F25: =D25-E25+F24 -> 3833766.2
A26: 45086 | B26: Crédito em conta | C26: MOEMA BIOENERGIA S A | D26: 332407.53 | F26: =D26-E26+F25 -> 4166173.7
A27: 45086 | B27: Gestão de caixa | E27: =(D26*0.005)+10 -> 1672.0377 | F27: =D27-E27+F26 -> 4164501.7
A28: 45086 | B28: Crédito em conta | C28: GUARIROBA BIOENERGIA LTDA | D28: 183280.34 | F28: =D28-E28+F27 -> 4347782
A29: 45086 | B29: Gestão de caixa | E29: =(D28*0.005)+10 -> 926.4017 | F29: =D29-E29+F28 -> 4346855.6
A30: 45089 | B30: Transferência entre contas | C30: TRANSPORTADORA TURISTICA BENFICA S.A | E30: 120000 | F30: =D30-E30+F29 -> 4226855.6
A31: 45089 | B31: Crédito em conta | C31: SANCETUR - SANTA CECILIA TURISMO LTDA | D31: 18000 | F31: =D31-E31+F30 -> 4244855.6
A32: 45089 | B32: Gestão de caixa | E32: =(D31*0.005)+10 -> 100 | F32: =D32-E32+F31 -> 4244755.6
A33: 45090 | B33: Transferência entre contas | C33: TRANSPORTADORA TURISTICA BENFICA S.A | E33: 2000 | F33: =D33-E33+F32 -> 4242755.6
A34: 45090 | B34: Transferência entre contas | C34: TRANSPORTADORA TURISTICA BENFICA S.A | E34: 1200 | F34: =D34-E34+F33 -> 4241555.6
A35: 45092 | B35: Transferência entre contas | C35: TRANSPORTADORA TURISTICA BENFICA S.A | E35: 95000 | F35: =D35-E35+F34 -> 4146555.6
A36: 45092 | B36: Crédito em conta | C36: TRANSPORTADORA TURISTICA BENFICA S.A | D36: 16030 | F36: =D36-E36+F35 -> 4162585.6
A37: 45092 | B37: Gestão de caixa | E37: =(D36*0.005)+10 -> 90.15 | F37: =D37-E37+F36 -> 4162495.5
A38: 45093 | B38: Transferência entre contas | C38: TRANSPORTADORA TURISTICA BENFICA S.A | E38: 11000 | F38: =D38-E38+F37 -> 4151495.5
A39: 45093 | B39: Transferência entre contas | C39: TRANSPORTADORA TURISTICA BENFICA S.A | E39: 3000 | F39: =D39-E39+F38 -> 4148495.5
A40: 45093 | B40: Crédito em conta | C40: SILVA & BEGHINI COMERCIO DE ONIBUS LTDA | D40: 13000 | F40: =D40-E40+F39 -> 4161495.5
A41: 45093 | B41: Gestão de caixa | E41: =(D40*0.005)+10 -> 75 | F41: =D41-E41+F40 -> 4161420.5
A42: 45096 | B42: Crédito em conta | C42: UNIVERSAL TURISMO LTDA-EPP | D42: 18000 | F42: =D42-E42+F41 -> 4179420.5
A43: 45096 | B43: Gestão de caixa | E43: =(D42*0.005)+10 -> 100 | F43: =D43-E43+F42 -> 4179320.5
...

Sheet Julho2023
A2: EXTRATO DE MOVIMENTAÇÃO
A4: Banco | B4: LEPTA BANK (274) | C4: Agência | D4: 1 | E4: Conta | F4: 08198095-5
A5: Empresa | B5: TRANSP. TURISTICA BENFICA S.A | C5: Saldo Anterior | D5: =Junho2023!F6 -> 4311864.2 | F5: Saldo Disponível
A6: CNPJ | B6: 59.275.289/0001-02 | C6: Totais (Entradas/Saídas) | D6: =SUM(D9:D609) -> 1826393.8 | E6: =SUM(E9:E609) -> 2288162 | F6: =F609 -> 3850096
A8: Data | B8: Histórico | C8: Complemento | D8: Créditos | E8: Débitos | F8: Saldo
A9: 45110 | B9: Tarifa de manutenção de conta | C9: TRANSPORTADORA TURISTICA BENFICA S.A - (Vinculada) | E9: 1500 | F9: =D9-E9+D5 -> 4310364.2
A10: 45110 | B10: Tarifa de manutenção da conta | C10: TED's, PIX e demais | E10: 440 | F10: =D10-E10+F9 -> 4309924.2
A11: 45110 | B11: Ajuste de Saldo | D11: 0.01 | F11: =D11-E11+F10 -> 4309924.2
A12: 45110 | B12: Crédito em conta | C12: PERFICE DO BRASIL SERVICOS DE TRANSPORTE E LOGISTICA LTDA | D12: 33250 | F12: =D12-E12+F11 -> 4343174.2
A13: 45110 | B13: Gestão de caixa | E13: =(D12*0.005)+10 -> 176.25 | F13: =D13-E13+F12 -> 4342998
A14: 45110 | B14: Crédito em conta | C14: PERFICE DO BRASIL SERVICOS DE TRANSPORTE E LOGISTICA LTDA | D14: 38135 | F14: =D14-E14+F13 -> 4381133
A15: 45110 | B15: Gestão de caixa | E15: =(D14*0.005)+10 -> 200.675 | F15: =D15-E15+F14 -> 4380932.3
A16: 45110 | B16: Transferência entre contas | C16: TRANSPORTADORA TURISTICA BENFICA S.A | E16: 21000 | F16: =D16-E16+F15 -> 4359932.3
A17: 45111 | B17: Tarifa de manutenção de conta | C17: TRANSPORTADORA TURISTICA BENFICA S.A - (Empresa) | E17: 1500 | F17: =D17-E17+F16 -> 4358432.3
A18: 45111 | B18: Transferência entre contas | C18: TRANSPORTADORA TURISTICA BENFICA S.A | E18: 447860 | F18: =D18-E18+F17 -> 3910572.3
A19: 45111 | B19: Transferência entre contas | C19: TRANSPORTADORA TURISTICA BENFICA S.A | E19: 30000 | F19: =D19-E19+F18 -> 3880572.3
A20: 45111 | B20: Crédito em conta | C20: TRANSPORTADORA TURISTICA BENFICA S.A | D20: 80000 | F20: =D20-E20+F19 -> 3960572.3
A21: 45111 | B21: Gestão de caixa | E21: =(D20*0.005)+10 -> 410 | F21: =D21-E21+F20 -> 3960162.3
A22: 45112 | B22: Crédito em conta | C22: BB TRANSPORTE E TURISMO LTDA | D22: 90000 | F22: =D22-E22+F21 -> 4050162.3
A23: 45112 | B23: Gestão de caixa | E23: =(D22*0.005)+10 -> 460 | F23: =D23-E23+F22 -> 4049702.3
A24: 45112 | B24: Transferência entre contas | C24: TRANSPORTADORA TURISTICA BENFICA S.A | E24: 212000 | F24: =D24-E24+F23 -> 3837702.3
A25: 45112 | B25: Transferência entre contas | C25: TRANSPORTADORA TURISTICA BENFICA S.A | E25: 79000 | F25: =D25-E25+F24 -> 3758702.3
A26: 45112 | B26: Ajuste de Saldo | E26: 0.01 | F26: =D26-E26+F25 -> 3758702.3
A27: 45113 | B27: Crédito em conta | C27: TRANSPORTADORA TURISTICA BENFICA S.A | D27: 19000 | F27: =D27-E27+F26 -> 3777702.3
A28: 45113 | B28: Gestão de caixa | E28: =(D27*0.005)+10 -> 105 | F28: =D28-E28+F27 -> 3777597.3
A29: 45113 | B29: Transferência entre contas | C29: TRANSPORTADORA TURISTICA BENFICA S.A | E29: 338000 | F29: =D29-E29+F28 -> 3439597.3
A30: 45114 | B30: Crédito em conta | C30: ARENA FUTIBA LTDA | D30: 707.01 | F30: =D30-E30+F29 -> 3440304.3
A31: 45114 | B31: Gestão de caixa | E31: =(D30*0.005)+10 -> 13.53505 | F31: =D31-E31+F30 -> 3440290.8
A32: 45114 | B32: Transferência entre contas | C32: TRANSPORTADORA TURISTICA BENFICA S.A | E32: 45000 | F32: =D32-E32+F31 -> 3395290.8
A33: 45114 | B33: Transferência entre contas | C33: TRANSPORTADORA TURISTICA BENFICA S.A | E33: 2500 | F33: =D33-E33+F32 -> 3392790.8
A34: 45117 | B34: Crédito em conta | C34: PATRIMONY ADMINISTRADORA DE BENS AS | D34: 152544 | F34: =D34-E34+F33 -> 3545334.8
A35: 45117 | B35: Gestão de caixa | E35: =(D34*0.005)+10 -> 772.72 | F35: =D35-E35+F34 -> 3544562
A36: 45117 | B36: Transferência entre contas | C36: TRANSPORTADORA TURISTICA BENFICA S.A | E36: 131000 | F36: =D36-E36+F35 -> 3413562
A37: 45117 | B37: Transferência entre contas | C37: TRANSPORTADORA TURISTICA BENFICA S.A | E37: 4000 | F37: =D37-E37+F36 -> 3409562
A38: 45117 | B38: Crédito em conta | C38: SANCETUR - SANTA CECILIA TURISMO LTDA | D38: 18000 | F38: =D38-E38+F37 -> 3427562
A39: 45117 | B39: Gestão de caixa | E39: =(D38*0.005)+10 -> 100 | F39: =D39-E39+F38 -> 3427462
A40: 45118 | B40: Crédito em conta | C40: MENDES FERREIRA AGRICOLA LTDA | D40: 8000 | F40: =D40-E40+F39 -> 3435462
A41: 45118 | B41: Gestão de caixa | E41: =(D40*0.005)+10 -> 50 | F41: =D41-E41+F40 -> 3435412
A42: 45118 | B42: Crédito em conta | C42: GUARIROBA BIOENERGIA LTDA | D42: 198183.88 | F42: =D42-E42+F41 -> 3633595.9
A43: 45118 | B43: Gestão de caixa | E43: =(D42*0.005)+10 -> 1000.9194 | F43: =D43-E43+F42 -> 3632595
...

Sheet Agosto2023
A2: EXTRATO DE MOVIMENTAÇÃO
A4: Banco | B4: LEPTA BANK (274) | C4: Agência | D4: 1 | E4: Conta | F4: 08198095-5
A5: Empresa | B5: TRANSP. TURISTICA BENFICA S.A | C5: Saldo Anterior | D5: =Julho2023!F6 -> 3850096 | F5: Saldo Disponível
A6: CNPJ | B6: 59.275.289/0001-02 | C6: Totais (Entradas/Saídas) | D6: =SUM(D9:D609) -> 1309666.8 | E6: =SUM(E9:E609) -> 1169768.3 | F6: =F609 -> 3989994.5
A8: Data | B8: Histórico | C8: Complemento | D8: Créditos | E8: Débitos | F8: Saldo
A9: 45139 | B9: Transferência entre contas | C9: TRANSPORTADORA TURISTICA BENFICA S.A | E9: 25500 | F9: =D9-E9+D5 -> 3824596
A10: 45140 | B10: Crédito em conta | C10: TRANSPORTADORA TURISTICA BENFICA S.A | D10: 93000 | F10: =D10-E10+F9 -> 3917596
A11: 45140 | B11: Gestão de caixa | E11: =(D10*0.005)+10 -> 475 | F11: =D11-E11+F10 -> 3917121
A12: 45140 | B12: Crédito em conta | C12: TRANSPORTADORA TURISTICA BENFICA S.A | D12: 23747.85 | F12: =D12-E12+F11 -> 3940868.8
A13: 45140 | B13: Gestão de caixa | E13: =(D12*0.005)+10 -> 128.73925 | F13: =D13-E13+F12 -> 3940740.1
A14: 45141 | B14: Tarifa de manutenção de conta | C14: TRANSPORTADORA TURISTICA BENFICA S.A - (Vinculada) | E14: 1500 | F14: =D14-E14+F13 -> 3939240.1
A15: 45141 | B15: Tarifa de manutenção da conta | C15: TED's, PIX e demais | E15: 420 | F15: =D15-E15+F14 -> 3938820.1
A16: 45141 | B16: Transferência entre contas | C16: TRANSPORTADORA TURISTICA BENFICA S.A | E16: 19000 | F16: =D16-E16+F15 -> 3919820.1
A17: 45141 | B17: Transferência entre contas | C17: TRANSPORTADORA TURISTICA BENFICA S.A | E17: 176000 | F17: =D17-E17+F16 -> 3743820.1
A18: 45141 | B18: Transferência entre contas | C18: TRANSPORTADORA TURISTICA BENFICA S.A | E18: 3000 | F18: =D18-E18+F17 -> 3740820.1
A19: 45142 | B19: Tarifa de manutenção de conta | C19: TRANSPORTADORA TURISTICA BENFICA S.A - (Empresa) | E19: 1500 | F19: =D19-E19+F18 -> 3739320.1
A20: 45142 | B20: Transferência entre contas | C20: TRANSPORTADORA TURISTICA BENFICA S.A | E20: 22500 | F20: =D20-E20+F19 -> 3716820.1
A21: 45142 | B21: Transferência entre contas | C21: TRANSPORTADORA TURISTICA BENFICA S.A | E21: 63000 | F21: =D21-E21+F20 -> 3653820.1
A22: 45142 | B22: Transferência entre contas | C22: TRANSPORTADORA TURISTICA BENFICA S.A | E22: 2500 | F22: =D22-E22+F21 -> 3651320.1
A23: 45142 | B23: Crédito em conta | C23: ARENA FUTIBA | D23: 3707.01 | F23: =D23-E23+F22 -> 3655027.1
A24: 45142 | B24: Gestão de caixa | E24: =(D23*0.005)+10 -> 28.53505 | F24: =D24-E24+F23 -> 3654998.6
A25: 45142 | B25: Crédito em conta | C25: LUBRIFICANTES S. K. LTDA | D25: 1190.7 | F25: =D25-E25+F24 -> 3656189.3
A26: 45142 | B26: Gestão de caixa | E26: =(D25*0.005)+10 -> 15.9535 | F26: =D26-E26+F25 -> 3656173.3
A27: 45145 | B27: Crédito em conta | C27: BB TRANSPORTE E TURISMO LTDA | D27: 90000 | F27: =D27-E27+F26 -> 3746173.3
A28: 45145 | B28: Gestão de caixa | E28: =(D27*0.005)+10 -> 460 | F28: =D28-E28+F27 -> 3745713.3
A29: 45145 | B29: Transferência entre contas | C29: TRANSPORTADORA TURISTICA BENFICA S.A | E29: 52000 | F29: =D29-E29+F28 -> 3693713.3
A30: 45145 | B30: Transferência entre contas | C30: TRANSPORTADORA TURISTICA BENFICA S.A | E30: 2000 | F30: =D30-E30+F29 -> 3691713.3
A31: 45146 | B31: Crédito em conta | C31: GUARIROBA BIOENERGIA LTDA | D31: 181682.6 | F31: =D31-E31+F30 -> 3873395.9
A32: 45146 | B32: Gestão de caixa | E32: =(D31*0.005)+10 -> 918.413 | F32: =D32-E32+F31 -> 3872477.5
A33: 45146 | B33: Crédito em conta | C33: MOEMA BIOENERGIA S A | D33: 224615.81 | F33: =D33-E33+F32 -> 4097093.3
A34: 45146 | B34: Gestão de caixa | E34: =(D33*0.005)+10 -> 1133.0791 | F34: =D34-E34+F33 -> 4095960.2
A35: 45146 | B35: Crédito em conta | C35: OUROESTE BIOENERGIA LTDA | D35: 23696.9 | F35: =D35-E35+F34 -> 4119657.1
A36: 45146 | B36: Gestão de caixa | E36: =(D35*0.005)+10 -> 128.4845 | F36: =D36-E36+F35 -> 4119528.7
A37: 45147 | B37: Crédito em conta | C37: TRANSPORTADORA TURISTICA BENFICA AS | D37: 22400 | F37: =D37-E37+F36 -> 4141928.7
A38: 45147 | B38: Gestão de caixa | E38: =(D37*0.005)+10 -> 122 | F38: =D38-E38+F37 -> 4141806.7
A39: 45147 | B39: Crédito em conta | C39: TRANSPORTADORA TURISTICA BENFICA AS | D39: 152524 | F39: =D39-E39+F38 -> 4294330.7
A40: 45147 | B40: Gestão de caixa | E40: =(D39*0.005)+10 -> 772.62 | F40: =D40-E40+F39 -> 4293558
A41: 45148 | B41: Transferência entre contas | C41: TRANSPORTADORA TURISTICA BENFICA S.A | E41: 141500 | F41: =D41-E41+F40 -> 4152058
A42: 45148 | B42: Transferência entre contas | C42: TRANSPORTADORA TURISTICA BENFICA S.A | E42: 16500 | F42: =D42-E42+F41 -> 4135558
A43: 45148 | B43: Crédito em conta | C43: SANCETUR - SANTA CECILIA TURISMO LTDA | D43: 15000 | F43: =D43-E43+F42 -> 4150558
...

Sheet Setembro2023
A2: EXTRATO DE MOVIMENTAÇÃO
A4: Banco | B4: LEPTA BANK (274) | C4: Agência | D4: 1 | E4: Conta | F4: 08198095-5
A5: Empresa | B5: TRANSP. TURISTICA BENFICA S.A | C5: Saldo Anterior | D5: =Agosto2023!F6 -> 3989994.5 | F5: Saldo Disponível
A6: CNPJ | B6: 59.275.289/0001-02 | C6: Totais (Entradas/Saídas) | D6: =SUM(D9:D609) -> 1112643 | E6: =SUM(E9:E609) -> 951483.22 | F6: =F609 -> 4151154.3
A8: Data | B8: Histórico | C8: Complemento | D8: Créditos | E8: Débitos | F8: Saldo
A9: 45170 | B9: Crédito em conta | C9: OTACILIO GOMES FERRAZ FILHO | D9: 13125 | F9: =D9-E9+D5 -> 4003119.5
A10: 45170 | B10: Gestão de caixa | E10: =(D9*0.005)+10 -> 75.625 | F10: =D10-E10+F9 -> 4003043.9
A11: 45172 | B11: Tarifa de manutenção de conta | C11: TRANSPORTADORA TURISTICA BENFICA S.A - (Vinculada) | E11: 1500 | F11: =D11-E11+F10 -> 4001543.9
A12: 45172 | B12: Tarifa de manutenção da conta | C12: TED's, PIX e demais | E12: 420 | F12: =D12-E12+F11 -> 4001123.9
A13: 45173 | B13: Crédito em conta | C13: TRANSPORTADORA TURISTICA BENFICA S.A | D13: 50000 | F13: =D13-E13+F12 -> 4051123.9
A14: 45173 | B14: Gestão de caixa | E14: =(D13*0.005)+10 -> 260 | F14: =D14-E14+F13 -> 4050863.9
A15: 45174 | B15: Crédito em conta | C15: BB TRANSPORTE E TURISMO LTDA | D15: 90000 | F15: =D15-E15+F14 -> 4140863.9
A16: 45174 | B16: Gestão de caixa | E16: =(D15*0.005)+10 -> 460 | F16: =D16-E16+F15 -> 4140403.9
A17: 45174 | B17: Crédito em conta | C17: GERACAO TRANSPORTES E LOCADORA DE VEICUL | D17: 120000 | F17: =D17-E17+F16 -> 4260403.9
A18: 45174 | B18: Gestão de caixa | E18: =(D17*0.005)+10 -> 610 | F18: =D18-E18+F17 -> 4259793.9
A19: 45174 | B19: Transferência entre contas | C19: TRANSPORTADORA TURISTICA BENFICA S.A | E19: 186000 | F19: =D19-E19+F18 -> 4073793.9
A20: 45174 | B20: Transferência entre contas | C20: TRANSPORTADORA TURISTICA BENFICA S.A | E20: 1000 | F20: =D20-E20+F19 -> 4072793.9
A21: 45175 | B21: Transferência entre contas | C21: TRANSPORTADORA TURISTICA BENFICA S.A | E21: 81000 | F21: =D21-E21+F20 -> 3991793.9
A22: 45175 | B22: Transferência entre contas | C22: TRANSPORTADORA TURISTICA BENFICA S.A | E22: 73000 | F22: =D22-E22+F21 -> 3918793.9
A23: 45175 | B23: Tarifa de manutenção de conta | C23: TRANSPORTADORA TURISTICA BENFICA S.A - (Empresa) | E23: 1500 | F23: =D23-E23+F22 -> 3917293.9
A24: 45177 | B24: Crédito em conta | C24: GUARIROBA BIOENERGIA LTDA | D24: 154450.08 | F24: =D24-E24+F23 -> 4071743.9
A25: 45177 | B25: Gestão de caixa | E25: =(D24*0.005)+10 -> 782.2504 | F25: =D25-E25+F24 -> 4070961.7
A26: 45177 | B26: Crédito em conta | C26: MOEMA BIOENERGIA S A | D26: 203313.03 | F26: =D26-E26+F25 -> 4274274.7
A27: 45177 | B27: Gestão de caixa | E27: =(D26*0.005)+10 -> 1026.5651 | F27: =D27-E27+F26 -> 4273248.2
A28: 45177 | B28: Crédito em conta | C28: OUROESTE BIOENERGIA LTDA | D28: 25171.69 | F28: =D28-E28+F27 -> 4298419.9
A29: 45177 | B29: Gestão de caixa | E29: =(D28*0.005)+10 -> 135.85845 | F29: =D29-E29+F28 -> 4298284
A30: 45180 | B30: Crédito em conta | C30: REGINALDO DA SILVA ALVES | D30: 140650 | F30: =D30-E30+F29 -> 4438934
A31: 45180 | B31: Gestão de caixa | E31: =(D30*0.005)+10 -> 713.25 | F31: =D31-E31+F30 -> 4438220.7
A32: 45180 | B32: Transferência entre contas | C32: TRANSPORTADORA TURISTICA BENFICA S.A | E32: 113000 | F32: =D32-E32+F31 -> 4325220.7
A33: 45181 | B33: Crédito em conta | C33: TRANSPORTADORA TUR BENFICA S A | D33: 147854 | F33: =D33-E33+F32 -> 4473074.7
A34: 45181 | B34: Gestão de caixa | E34: =(D33*0.005)+10 -> 749.27 | F34: =D34-E34+F33 -> 4472325.5
A35: 45181 | B35: Crédito em conta | C35: SANCETUR - SANTA CECILIA TURISMO LTDA | D35: 12000 | F35: =D35-E35+F34 -> 4484325.5
A36: 45181 | B36: Gestão de caixa | E36: =(D35*0.005)+10 -> 70 | F36: =D36-E36+F35 -> 4484255.5
A37: 45182 | B37: Transferência entre contas | C37: TRANSPORTADORA TURISTICA BENFICA S.A | E37: 34000 | F37: =D37-E37+F36 -> 4450255.5
A38: 45183 | B38: Transferência entre contas | C38: TRANSPORTADORA TURISTICA BENFICA S.A | E38: 20000 | F38: =D38-E38+F37 -> 4430255.5
A39: 45184 | B39: Transferência entre contas | C39: TRANSPORTADORA TURISTICA BENFICA S.A | E39: 37500 | F39: =D39-E39+F38 -> 4392755.5
A40: 45184 | B40: Crédito em conta | C40: SCATENA AGENCIA DE VIAGENS E TURISMO EIR | D40: 23333.33 | F40: =D40-E40+F39 -> 4416088.8
A41: 45184 | B41: Gestão de caixa | E41: =(D40*0.005)+10 -> 126.66665 | F41: =D41-E41+F40 -> 4415962.1
A42: 45187 | B42: Transferência entre contas | C42: TRANSPORTADORA TURISTICA BENFICA S.A | E42: 82000 | F42: =D42-E42+F41 -> 4333962.1
A43: 45188 | B43: Crédito em conta | C43: ANANIAS MORICIO DA SILVA | D43: 11000 | F43: =D43-E43+F42 -> 4344962.1
...

Sheet Outubro2023
A2: EXTRATO DE MOVIMENTAÇÃO
A4: Banco | B4: LEPTA BANK (274) | C4: Agência | D4: 1 | E4: Conta | F4: 08198095-5
A5: Empresa | B5: TRANSP. TURISTICA BENFICA S.A | C5: Saldo Anterior | D5: =Setembro2023!F6 -> 4151154.3 | F5: Saldo Disponível
A6: CNPJ | B6: 59.275.289/0001-02 | C6: Totais (Entradas/Saídas) | D6: =SUM(D9:D609) -> 1738820.8 | E6: =SUM(E9:E609) -> 2615004.1 | F6: =F609 -> 3274971
A8: Data | B8: Histórico | C8: Complemento | D8: Créditos | E8: Débitos | F8: Saldo
A9: 45200 | B9: Tarifa de manutenção de conta | C9: TRANSPORTADORA TURISTICA BENFICA S.A - (Vinculada) | E9: 1500 | F9: =D9-E9+D5 -> 4149654.3
A10: 45200 | B10: Tarifa de manutenção da conta | C10: TED's, PIX e demais | E10: 300 | F10: =D10-E10+F9 -> 4149354.3
A11: 45201 | B11: Transferência entre contas | C11: TRANSPORTADORA TURISTICA BENFICA S.A | E11: 9500 | F11: =D11-E11+F10 -> 4139854.3
A12: 45202 | B12: Transferência entre contas | C12: TRANSPORTADORA TURISTICA BENFICA S.A | E12: 12000 | F12: =D12-E12+F11 -> 4127854.3
A13: 45203 | B13: Transferência entre contas | C13: TRANSPORTADORA TURISTICA BENFICA S.A | E13: 184000 | F13: =D13-E13+F12 -> 3943854.3
A14: 45204 | B14: Crédito em conta | C14: BB TRANSPORTE E TURISMO LTDA | D14: 90000 | F14: =D14-E14+F13 -> 4033854.3
A15: 45204 | B15: Gestão de caixa | E15: =(D14*0.005)+10 -> 460 | F15: =D15-E15+F14 -> 4033394.3
A16: 45204 | B16: Transferência entre contas | C16: TRANSPORTADORA TURISTICA BENFICA S.A | E16: 1000 | F16: =D16-E16+F15 -> 4032394.3
A17: 45204 | B17: Tarifa de manutenção de conta | C17: TRANSPORTADORA TURISTICA BENFICA S.A - (Empresa) | E17: 1500 | F17: =D17-E17+F16 -> 4030894.3
A18: 45205 | B18: Transferência entre contas | C18: TRANSPORTADORA TURISTICA BENFICA S.A | E18: 38000 | F18: =D18-E18+F17 -> 3992894.3
A19: 45205 | B19: Transferência entre contas | C19: TRANSPORTADORA TURISTICA BENFICA S.A | E19: 26800 | F19: =D19-E19+F18 -> 3966094.3
A20: 45208 | B20: Transferência entre contas | C20: TRANSPORTADORA TURISTICA BENFICA S.A | E20: 309000 | F20: =D20-E20+F19 -> 3657094.3
A21: 45208 | B21: Crédito em conta | C21: TRANSPORTADORA TUR BENFICA S A | D21: 152524 | F21: =D21-E21+F20 -> 3809618.3
A22: 45208 | B22: Gestão de caixa | E22: =(D21*0.005)+10 -> 772.62 | F22: =D22-E22+F21 -> 3808845.6
A23: 45209 | B23: Crédito em conta | C23: WALTER GONCALVES CUNHA | D23: 40000 | F23: =D23-E23+F22 -> 3848845.6
A24: 45209 | B24: Gestão de caixa | E24: =(D23*0.005)+10 -> 210 | F24: =D24-E24+F23 -> 3848635.6
A25: 45209 | B25: Transferência entre contas | C25: TRANSPORTADORA TURISTICA BENFICA S.A | E25: 276000 | F25: =D25-E25+F24 -> 3572635.6
A26: 45209 | B26: Crédito em conta | C26: SANCETUR - SANTA CECILIA TURISMO LTDA | D26: 12000 | F26: =D26-E26+F25 -> 3584635.6
A27: 45209 | B27: Gestão de caixa | E27: =(D26*0.005)+10 -> 70 | F27: =D27-E27+F26 -> 3584565.6
A28: 45209 | B28: Crédito em conta | C28: GUARIROBA BIOENERGIA LTDA | D28: 148110.22 | F28: =D28-E28+F27 -> 3732675.9
A29: 45209 | B29: Gestão de caixa | E29: =(D28*0.005)+10 -> 750.5511 | F29: =D29-E29+F28 -> 3731925.3
A30: 45209 | B30: Crédito em conta | C30: MOEMA BIOENERGIA S A | D30: 209326.27 | F30: =D30-E30+F29 -> 3941251.6
A31: 45209 | B31: Gestão de caixa | E31: =(D30*0.005)+10 -> 1056.6313 | F31: =D31-E31+F30 -> 3940195
A32: 45209 | B32: Transferência entre contas | C32: TRANSPORTADORA TURISTICA BENFICA S.A | E32: 495000 | F32: =D32-E32+F31 -> 3445195
A33: 45210 | B33: Crédito em conta | C33: OUROESTE BIOENERGIA LTDA | D33: 23689.39 | F33: =D33-E33+F32 -> 3468884.3
A34: 45210 | B34: Gestão de caixa | E34: =(D33*0.005)+10 -> 128.44695 | F34: =D34-E34+F33 -> 3468755.9
A35: 45210 | B35: Transferência entre contas | C35: TRANSPORTADORA TURISTICA BENFICA S.A | E35: 392000 | F35: =D35-E35+F34 -> 3076755.9
A36: 45215 | B36: Transferência entre contas | C36: TRANSPORTADORA TURISTICA BENFICA S.A | E36: 434000 | F36: =D36-E36+F35 -> 2642755.9
A37: 45215 | B37: Crédito em conta | C37: SCATENA AGENCIA DE VIAGENS E TURISMO EIR | D37: 11433.32 | F37: =D37-E37+F36 -> 2654189.2
A38: 45215 | B38: Gestão de caixa | E38: =(D37*0.005)+10 -> 67.1666 | F38: =D38-E38+F37 -> 2654122.1
A39: 45217 | B39: Transferência entre contas | C39: TRANSPORTADORA TURISTICA BENFICA S.A | E39: 86000 | F39: =D39-E39+F38 -> 2568122.1
A40: 45217 | B40: Crédito em conta | C40: 2 IRMAS TRANSPORTES LTDA | D40: 22500 | F40: =D40-E40+F39 -> 2590622.1
A41: 45217 | B41: Gestão de caixa | E41: =(D40*0.005)+10 -> 122.5 | F41: =D41-E41+F40 -> 2590499.6
A42: 45218 | B42: Transferência entre contas | C42: TRANSPORTADORA TURISTICA BENFICA S.A | E42: 10000 | F42: =D42-E42+F41 -> 2580499.6
A43: 45218 | B43: Crédito em conta | C43: BANCO DO BRASIL | D43: 43994.13 | F43: =D43-E43+F42 -> 2624493.7
...

Sheet Novembro2023
A2: EXTRATO DE MOVIMENTAÇÃO
A4: Banco | B4: LEPTA BANK (274) | C4: Agência | D4: 1 | E4: Conta | F4: 08198095-5
A5: Empresa | B5: TRANSP. TURISTICA BENFICA S.A | C5: Saldo Anterior | D5: =Outubro2023!F6 -> 3274971 | F5: Saldo Disponível
A6: CNPJ | B6: 59.275.289/0001-02 | C6: Totais (Entradas/Saídas) | D6: =SUM(D9:D609) -> 643484.69 | E6: =SUM(E9:E609) -> 607857.42 | F6: =F609 -> 3310598.3
A8: Data | B8: Histórico | C8: Complemento | D8: Créditos | E8: Débitos | F8: Saldo
A9: 45231 | B9: Tarifa de manutenção de conta | C9: TRANSPORTADORA TURISTICA BENFICA S.A - (Vinculada) | E9: 1500 | F9: =D9-E9+D5 -> 3273471
A10: 45231 | B10: Tarifa de manutenção da conta | C10: TED's, PIX e demais | E10: 380 | F10: =D10-E10+F9 -> 3273091
A11: 45231 | B11: Crédito em conta | C11: SILVANA DO NASCIMENTO RODRIGUES | D11: 25000 | F11: =D11-E11+F10 -> 3298091
A12: 45231 | B12: Gestão de caixa | E12: =(D11*0.005)+10 -> 135 | F12: =D12-E12+F11 -> 3297956
A13: 45231 | B13: Transferência entre contas | C13: TRANSPORTADORA TURISTICA BENFICA S.A | E13: 500 | F13: =D13-E13+F12 -> 3297456
A14: 45231 | B14: Crédito em conta | C14: ARD TRANSPORTES LTDA | D14: 10000 | F14: =D14-E14+F13 -> 3307456
A15: 45231 | B15: Gestão de caixa | E15: =(D14*0.005)+10 -> 60 | F15: =D15-E15+F14 -> 3307396
A16: 45233 | B16: Transferência entre contas | C16: TRANSPORTADORA TURISTICA BENFICA S.A | E16: 114000 | F16: =D16-E16+F15 -> 3193396
A17: 45233 | B17: Tarifa de manutenção de conta | C17: TRANSPORTADORA TURISTICA BENFICA S.A - (Empresa) | E17: 1500 | F17: =D17-E17+F16 -> 3191896
A18: 45236 | B18: Crédito em conta | C18: BB TRANSPORTE E TURISMO LTDA | D18: 90000 | F18: =D18-E18+F17 -> 3281896
A19: 45236 | B19: Gestão de caixa | E19: =(D18*0.005)+10 -> 460 | F19: =D19-E19+F18 -> 3281436
A20: 45236 | B20: Transferência entre contas | C20: TRANSPORTADORA TURISTICA BENFICA S.A | E20: 18500 | F20: =D20-E20+F19 -> 3262936
A21: 45236 | B21: Transferência entre contas | C21: TRANSPORTADORA TURISTICA BENFICA S.A | E21: 5800 | F21: =D21-E21+F20 -> 3257136
A22: 45237 | B22: Transferência entre contas | C22: TRANSPORTADORA TURISTICA BENFICA S.A | E22: 12000 | F22: =D22-E22+F21 -> 3245136
A23: 45238 | B23: Crédito em conta | C23: PATRIMONY ADMINISTRADORA DE BENS AS | D23: 152544 | F23: =D23-E23+F22 -> 3397680
A24: 45238 | B24: Gestão de caixa | E24: =(D23*0.005)+10 -> 772.72 | F24: =D24-E24+F23 -> 3396907.3
A25: 45238 | B25: Crédito em conta | C25: GUARIROBA BIOENERGIA LTDA | D25: 74445.38 | F25: =D25-E25+F24 -> 3471352.7
A26: 45238 | B26: Gestão de caixa | E26: =(D25*0.005)+10 -> 382.2269 | F26: =D26-E26+F25 -> 3470970.4
A27: 45238 | B27: Crédito em conta | C27: MOEMA BIOENERGIA S A | D27: 179372.93 | F27: =D27-E27+F26 -> 3650343.4
A28: 45238 | B28: Gestão de caixa | E28: =(D27*0.005)+10 -> 906.86465 | F28: =D28-E28+F27 -> 3649436.5
A29: 45239 | B29: Crédito em conta | C29: OUROESTE BIOENERGIA LTDA | D29: 11660.46 | F29: =D29-E29+F28 -> 3661097
A30: 45239 | B30: Gestão de caixa | E30: =(D29*0.005)+10 -> 68.3023 | F30: =D30-E30+F29 -> 3661028.6
A31: 45240 | B31: Crédito em conta | C31: SANCETUR - SANTA CECILIA TURISMO LTDA | D31: 12000 | F31: =D31-E31+F30 -> 3673028.6
A32: 45240 | B32: Gestão de caixa | E32: =(D31*0.005)+10 -> 70 | F32: =D32-E32+F31 -> 3672958.6
A33: 45240 | B33: Transferência entre contas | C33: TRANSPORTADORA TURISTICA BENFICA S.A | E33: 103000 | F33: =D33-E33+F32 -> 3569958.6
A34: 45244 | B34: Transferência entre contas | C34: TRANSPORTADORA TURISTICA BENFICA S.A | E34: 7000 | F34: =D34-E34+F33 -> 3562958.6
A35: 45246 | B35: Crédito em conta | C35: TED Recebida | D35: 8.77 | F35: =D35-E35+F34 -> 3562967.4
A36: 45246 | B36: Gestão de caixa | E36: =(D35*0.005)+10 -> 10.04385 | F36: =D36-E36+F35 -> 3562957.4
A37: 45247 | B37: Transferência entre contas | C37: TRANSPORTADORA TURISTICA BENFICA S.A | E37: 54000 | F37: =D37-E37+F36 -> 3508957.4
A38: 45247 | B38: Ajuste de Saldo | D38: 0.01 | F38: =D38-E38+F37 -> 3508957.4
A39: 45247 | B39: Transferência entre contas | C39: TRANSPORTADORA TURISTICA BENFICA S.A | E39: 1000 | F39: =D39-E39+F38 -> 3507957.4
A40: 45250 | B40: Crédito em conta | C40: ARENA FUTIBA II | D40: 10707.01 | F40: =D40-E40+F39 -> 3518664.4
A41: 45250 | B41: Gestão de caixa | E41: =(D40*0.005)+10 -> 63.53505 | F41: =D41-E41+F40 -> 3518600.9
A42: 45251 | B42: Transferência entre contas | C42: TRANSPORTADORA TURISTICA BENFICA S.A | E42: 81000 | F42: =D42-E42+F41 -> 3437600.9
A43: 45251 | B43: Crédito em conta | C43: SCATENA AGENCIA DE VIAGENS E TURISMO LTDA | D43: 7000 | F43: =D43-E43+F42 -> 3444600.9
...

Sheet Dezembro2023
A2: EXTRATO DE MOVIMENTAÇÃO
A4: Banco | B4: LEPTA BANK (274) | C4: Agência | D4: 1 | E4: Conta | F4: 08198095-5
A5: Empresa | B5: TRANSP. TURISTICA BENFICA S.A | C5: Saldo Anterior | D5: =Novembro2023!F6 -> 3310598.3 | F5: Saldo Disponível
A6: CNPJ | B6: 59.275.289/0001-02 | C6: Totais (Entradas/Saídas) | D6: =SUM(D9:D609) -> 570482.81 | E6: =SUM(E9:E609) -> 655072.43 | F6: =F609 -> 3226008.6
A8: Data | B8: Histórico | C8: Complemento | D8: Créditos | E8: Débitos | F8: Saldo
A9: 45261 | B9: Tarifa de manutenção de conta | C9: TRANSPORTADORA TURISTICA BENFICA S.A - (Vinculada) | E9: 1500 | F9: =D9-E9+D5 -> 3309098.3
A10: 45261 | B10: Tarifa de manutenção da conta | C10: TED's, PIX e demais | E10: 320 | F10: =D10-E10+F9 -> 3308778.3
A11: 45264 | B11: Transferência entre contas | C11: TRANSPORTADORA TURISTICA BENFICA S.A | E11: 108000 | F11: =D11-E11+F10 -> 3200778.3
A12: 45264 | B12: Transferência entre contas | C12: TRANSPORTADORA TURISTICA BENFICA S.A | E12: 14000 | F12: =D12-E12+F11 -> 3186778.3
A13: 45267 | B13: Crédito em conta | C13: BB TRANSPORTE E TURISMO LTDA | D13: 90000 | F13: =D13-E13+F12 -> 3276778.3
A14: 45267 | B14: Gestão de caixa | E14: =(D13*0.005)+10 -> 460 | F14: =D14-E14+F13 -> 3276318.3
A15: 45267 | B15: Crédito em conta | C15: JOSE APARECIDO MENDES RAMOS | D15: 40000 | F15: =D15-E15+F14 -> 3316318.3
A16: 45267 | B16: Gestão de caixa | E16: =(D15*0.005)+10 -> 210 | F16: =D16-E16+F15 -> 3316108.3
A17: 45267 | B17: Transferência entre contas | C17: TRANSPORTADORA TURISTICA BENFICA S.A | E17: 31500 | F17: =D17-E17+F16 -> 3284608.3
A18: 45267 | B18: Transferência entre contas | C18: TRANSPORTADORA TURISTICA BENFICA S.A | E18: 3100 | F18: =D18-E18+F17 -> 3281508.3
A19: 45268 | B19: Ajuste de saldo | E19: 0.01 | F19: =D19-E19+F18 -> 3281508.2
A20: 45271 | B20: Transferência entre contas | C20: TRANSPORTADORA TURISTICA BENFICA S.A | E20: 77500 | F20: =D20-E20+F19 -> 3204008.2
A21: 45271 | B21: Transferência entre contas | C21: TRANSPORTADORA TURISTICA BENFICA S.A | E21: 2000 | F21: =D21-E21+F20 -> 3202008.2
A22: 45271 | B22: Crédito em conta | C22: SANCETUR - SANTA CECILIA TURISMO LTDA | D22: 6000 | F22: =D22-E22+F21 -> 3208008.2
A23: 45271 | B23: Gestão de caixa | E23: =(D22*0.005)+10 -> 40 | F23: =D23-E23+F22 -> 3207968.2
A24: 45272 | B24: Crédito em conta | C24: TRANSPORTADORA TUR BENFICA S A | D24: 161129.59 | F24: =D24-E24+F23 -> 3369097.8
A25: 45272 | B25: Gestão de caixa | E25: =(D24*0.005)+10 -> 815.64795 | F25: =D25-E25+F24 -> 3368282.2
A26: 45272 | B26: Tarifa de manutenção de conta | C26: TRANSPORTADORA TURISTICA BENFICA S.A - (Empresa) | E26: 1500 | F26: =D26-E26+F25 -> 3366782.2
A27: 45275 | B27: Crédito em conta | C27: TRANSPORTADORA TURISTICA BENFICA S.A | D27: 3500 | F27: =D27-E27+F26 -> 3370282.2
A28: 45275 | B28: Gestão de caixa | E28: =(D27*0.005)+10 -> 27.5 | F28: =D28-E28+F27 -> 3370254.7
A29: 45275 | B29: Crédito em conta | C29: TRANSPORTADORA TURISTICA BENFICA S.A | D29: 3000 | F29: =D29-E29+F28 -> 3373254.7
A30: 45275 | B30: Gestão de caixa | E30: =(D29*0.005)+10 -> 25 | F30: =D30-E30+F29 -> 3373229.7
A31: 45275 | B31: Crédito em conta | C31: ALESSANDRO R DOS SANTOS AGRICOLA E TRANSPORTE | D31: 7000 | F31: =D31-E31+F30 -> 3380229.7
A32: 45275 | B32: Gestão de caixa | E32: =(D31*0.005)+10 -> 45 | F32: =D32-E32+F31 -> 3380184.7
A33: 45275 | B33: Transferência entre contas | C33: TRANSPORTADORA TURISTICA BENFICA S.A | E33: 69000 | F33: =D33-E33+F32 -> 3311184.7
A34: 45275 | B34: Crédito em conta | C34: SCATENA AGENCIA DE VIAGENS E TURISMO LTDA | D34: 7000 | F34: =D34-E34+F33 -> 3318184.7
A35: 45275 | B35: Gestão de caixa | E35: =(D34*0.005)+10 -> 45 | F35: =D35-E35+F34 -> 3318139.7
A36: 45278 | B36: Crédito em conta | C36: DOCINI PROMOCAO DE VENDAS LTDA | D36: 24000 | F36: =D36-E36+F35 -> 3342139.7
A37: 45278 | B37: Gestão de caixa | E37: =(D36*0.005)+10 -> 130 | F37: =D37-E37+F36 -> 3342009.7
A38: 45278 | B38: Transferência entre contas | C38: TRANSPORTADORA TURISTICA BENFICA S.A | E38: 96000 | F38: =D38-E38+F37 -> 3246009.7
A39: 45278 | B39: Transferência entre contas | C39: TRANSPORTADORA TURISTICA BENFICA S.A | E39: 17000 | F39: =D39-E39+F38 -> 3229009.7
A40: 45279 | B40: Crédito em conta | C40: CELMA LINA DE ARAUJO ALMEIDA | D40: 20610 | F40: =D40-E40+F39 -> 3249619.7
A41: 45279 | B41: Gestão de caixa | E41: =(D40*0.005)+10 -> 113.05 | F41: =D41-E41+F40 -> 3249506.6
A42: 45279 | B42: Crédito em conta | C42: CELMA LINA DE ARAUJO ALMEIDA | D42: 3890 | F42: =D42-E42+F41 -> 3253396.6
A43: 45279 | B43: Gestão de caixa | E43: =(D42*0.005)+10 -> 29.45 | F43: =D43-E43+F42 -> 3253367.2
...

Sheet Janeiro2024
A2: EXTRATO DE MOVIMENTAÇÃO
A4: Banco | B4: LEPTA BANK (274) | C4: Agência | D4: 1 | E4: Conta | F4: 08198095-5
A5: Empresa | B5: TRANSP. TURISTICA BENFICA S.A | C5: Saldo Anterior | D5: =Dezembro2023!F6 -> 3226008.6 | F5: Saldo Disponível
A6: CNPJ | B6: 59.275.289/0001-02 | C6: Totais (Entradas/Saídas) | D6: =SUM(D9:D609) -> 416748.21 | E6: =SUM(E9:E609) -> 710773.75 | F6: =F609 -> 2931983.1
A8: Data | B8: Histórico | C8: Complemento | D8: Créditos | E8: Débitos | F8: Saldo
A9: 45292 | B9: Tarifa de manutenção de conta | C9: TRANSPORTADORA TURISTICA BENFICA S.A - (Vinculada) | E9: 1500 | F9: =D9-E9+D5 -> 3224508.6
A10: 45292 | B10: Tarifa de manutenção da conta | C10: TED's, PIX e demais | E10: 240 | F10: =D10-E10+F9 -> 3224268.6
A11: 45295 | B11: Transferência entre contas | C11: TRANSPORTADORA TURISTICA BENFICA S.A | E11: 201200 | F11: =D11-E11+F10 -> 3023068.6
A12: 45295 | B12: Transferência entre contas | C12: TRANSPORTADORA TURISTICA BENFICA S.A | E12: 7100 | F12: =D12-E12+F11 -> 3015968.6
A13: 45295 | B13: Transferência entre contas | C13: TRANSPORTADORA TURISTICA BENFICA S.A | E13: 1500 | F13: =D13-E13+F12 -> 3014468.6
A14: 45299 | B14: Crédito em conta | C14: BB TRANSPORTE E TURISMO LTDA | D14: 90000 | F14: =D14-E14+F13 -> 3104468.6
A15: 45299 | B15: Gestão de caixa | E15: =(D14*0.005)+10 -> 460 | F15: =D15-E15+F14 -> 3104008.6
A16: 45299 | B16: Crédito em conta | C16: PATRIMONY ADMINISTRADORA DE BENS AS | D16: 159617.63 | F16: =D16-E16+F15 -> 3263626.3
A17: 45299 | B17: Gestão de caixa | E17: =(D16*0.005)+10 -> 808.08815 | F17: =D17-E17+F16 -> 3262818.2
A18: 45301 | B18: Transferência entre contas | C18: TRANSPORTADORA TURISTICA BENFICA S.A | E18: 83500 | F18: =D18-E18+F17 -> 3179318.2
A19: 45301 | B19: Tarifa de manutenção de conta | C19: TRANSPORTADORA TURISTICA BENFICA S.A - (Empresa) | E19: 1500 | F19: =D19-E19+F18 -> 3177818.2
A20: 45301 | B20: Crédito em conta | C20: SANCETUR SANTA CECILIA TURISMO LTDA | D20: 6000 | F20: =D20-E20+F19 -> 3183818.2
A21: 45301 | B21: Gestão de caixa | E21: =(D20*0.005)+10 -> 40 | F21: =D21-E21+F20 -> 3183778.2
A22: 45302 | B22: Transferência entre contas | C22: TRANSPORTADORA TURISTICA BENFICA S.A | E22: 4000 | F22: =D22-E22+F21 -> 3179778.2
A23: 45302 | B23: Ajuste de Saldo | E23: 0.01 | F23: =D23-E23+F22 -> 3179778.2
A24: 45306 | B24: Transferência entre contas | C24: TRANSPORTADORA TURISTICA BENFICA S.A | E24: 47000 | F24: =D24-E24+F23 -> 3132778.2
A25: 45307 | B25: Transferência entre contas | C25: TRANSPORTADORA TURISTICA BENFICA S.A | E25: 1000 | F25: =D25-E25+F24 -> 3131778.2
A26: 45307 | B26: Crédito em conta | C26: CELMA LINA DE ARAUJO ALMEIDA | D26: 4500 | F26: =D26-E26+F25 -> 3136278.2
A27: 45307 | B27: Gestão de caixa | E27: =(D26*0.005)+10 -> 32.5 | F27: =D27-E27+F26 -> 3136245.7
A28: 45309 | B28: Transferência entre contas | C28: TRANSPORTADORA TURISTICA BENFICA S.A | E28: 1000 | F28: =D28-E28+F27 -> 3135245.7
A29: 45309 | B29: Transferência entre contas | C29: TRANSPORTADORA TURISTICA BENFICA S.A | E29: 146100 | F29: =D29-E29+F28 -> 2989145.7
A30: 45309 | B30: Transferência entre contas | C30: TRANSPORTADORA TURISTICA BENFICA S.A | E30: 9500 | F30: =D30-E30+F29 -> 2979645.7
A31: 45311 | B31: Crédito em conta | C31: ARENA FUTIBA II | D31: 10707.01 | F31: =D31-E31+F30 -> 2990352.7
A32: 45311 | B32: Gestão de caixa | E32: =(D31*0.005)+10 -> 63.53505 | F32: =D32-E32+F31 -> 2990289.1
A33: 45313 | B33: Crédito em conta | C33: TRANSPORTADORA TURISTICA BENFICA S.A | D33: 16000 | F33: =D33-E33+F32 -> 3006289.1
A34: 45313 | B34: Gestão de caixa | E34: =(D33*0.005)+10 -> 90 | F34: =D34-E34+F33 -> 3006199.1
A35: 45313 | B35: Crédito em conta | C35: TRANSPORTADORA TURISTICA BENFICA AS | D35: 1400 | F35: =D35-E35+F34 -> 3007599.1
A36: 45313 | B36: Gestão de caixa | E36: =(D35*0.005)+10 -> 17 | F36: =D36-E36+F35 -> 3007582.1
A37: 45314 | B37: Transferência entre contas | C37: TRANSPORTADORA TURISTICA BENFICA S.A | E37: 4800 | F37: =D37-E37+F36 -> 3002782.1
A38: 45316 | B38: Crédito em conta | C38: METAL 2 INDUSTRIA E COMERCIO LTDA | D38: 10252.51 | F38: =D38-E38+F37 -> 3013034.7
A39: 45316 | B39: Gestão de caixa | E39: =(D38*0.005)+10 -> 61.26255 | F39: =D39-E39+F38 -> 3012973.4
A40: 45316 | B40: Transferência entre contas | C40: TRANSPORTADORA TURISTICA BENFICA S.A | E40: 24000 | F40: =D40-E40+F39 -> 2988973.4
A41: 45316 | B41: Transferência entre contas | C41: TRANSPORTADORA TURISTICA BENFICA S.A | E41: 7200 | F41: =D41-E41+F40 -> 2981773.4
A42: 45317 | B42: Crédito em conta | C42: DOCINI PROMOCAO DE VENDAS LTDA | D42: 600 | F42: =D42-E42+F41 -> 2982373.4
A43: 45317 | B43: Gestão de caixa | E43: =(D42*0.005)+10 -> 13 | F43: =D43-E43+F42 -> 2982360.4
...

Sheet Fevereiro2024
A2: EXTRATO DE MOVIMENTAÇÃO
A4: Banco | B4: LEPTA BANK (274) | C4: Agência | D4: 1 | E4: Conta | F4: 08198095-5
A5: Empresa | B5: TRANSP. TURISTICA BENFICA S.A | C5: Saldo Anterior | D5: =Janeiro2024!F6 -> 2931983.1 | F5: Saldo Disponível
A6: CNPJ | B6: 59.275.289/0001-02 | C6: Totais (Entradas/Saídas) | D6: =SUM(D9:D609) -> 838086.9 | E6: =SUM(E9:E609) -> 425210.44 | F6: =F609 -> 3344859.5
A8: Data | B8: Histórico | C8: Complemento | D8: Créditos | E8: Débitos | F8: Saldo
A9: 45323 | B9: Crédito em conta | C9: AGROTERRA SERVICOS AGRICOLAS NOVO HORIZONTE LTDA | D9: 5000 | F9: =D9-E9+D5 -> 2936983.1
A10: 45323 | B10: Gestão de caixa | E10: =(D9*0.005)+10 -> 35 | F10: =D10-E10+F9 -> 2936948.1
A11: 45323 | B11: Crédito em conta | C11: AGROTERRA SERVICOS AGRICOLAS NOVO HORIZONTE LTDA | D11: 14000 | F11: =D11-E11+F10 -> 2950948.1
A12: 45323 | B12: Gestão de caixa | E12: =(D11*0.005)+10 -> 80 | F12: =D12-E12+F11 -> 2950868.1
A13: 45323 | B13: Crédito em conta | C13: AGROTERRA SERVICOS AGRICOLAS NOVO HORIZONTE LTDA | D13: 4500 | F13: =D13-E13+F12 -> 2955368.1
A14: 45323 | B14: Gestão de caixa | E14: =(D13*0.005)+10 -> 32.5 | F14: =D14-E14+F13 -> 2955335.6
A15: 45323 | B15: Crédito em conta | C15: AGROTERRA SERVICOS AGRICOLAS NOVO HORIZONTE LTDA | D15: 9000 | F15: =D15-E15+F14 -> 2964335.6
A16: 45323 | B16: Gestão de caixa | E16: =(D15*0.005)+10 -> 55 | F16: =D16-E16+F15 -> 2964280.6
A17: 45323 | B17: Tarifa de manutenção de conta | C17: TRANSPORTADORA TURISTICA BENFICA S.A - (Vinculada) | E17: 1500 | F17: =D17-E17+F16 -> 2962780.6
A18: 45323 | B18: Tarifa de manutenção da conta | C18: TED's, PIX e demais | E18: 360 | F18: =D18-E18+F17 -> 2962420.6
